<?xml version="1.0" encoding="utf-8"?>
<robot xmlns:xacro="http://www.ros.org/wiki/xacro" name="robot"/>
<!-- Open_Manipulator Chain -->
<!-- NOTES: Origin coordinates of joint is relative to parent link reference frame -->
<!-- NOTES: STL files are to be saved in mm, and no translating positive origin -->

  <!-- Base Link -->
  ////daefsdf
  <link name="base_link">
    <visual>
      <origin xyz="0 0 0.0" rpy="-1.57079632679 0 0"/>
      <geometry>
        <mesh filename="package://billee_bot/meshes/0_Base_link.STL" scale="0.001 0.001 0.001"/>
      </geometry>
      <material name = "gray A">
		    <color rgba = "1 0.1 0.1 1" />
	    </material>
      
    </visual>

    <collision>
      <origin xyz="0 0 0.0" rpy="1.57079632679 0 0"/>
      <geometry>
        <mesh filename="package://billee_bot/meshes/0_Base_link.STL" scale="0.001 0.001 0.001"/>
      </geometry>
    </collision>

    <inertial>
      <origin xyz="0.0 0.0000000e+00 0.0" />
      <mass value="1.15973" />
      <inertia ixx="0.071425" ixy="0.0" ixz="0.0"
               iyy="0.001583" iyz="0.0"
               izz="0.069989" />
    </inertial>
  </link>

<!--  Base joint 1-->
  <joint name="mech_joint1" type="revolute">
    <parent link="base_link"/>
    <child link="link1"/>
	<!-- y = -0.8377 -->
    <origin xyz="0 0 0.0607" rpy="3.14159265 0 0"/>
    <axis xyz="0 0 1"/>
    <limit velocity="4.8" effort="1" lower="-4.1" upper="4.1" />
  </joint>

  <!--  Link 1 -->
  <link name="link1">
    <visual>
      <origin xyz="0 0 0" rpy="0 0 0"/>
      <geometry>
        <mesh filename="package://billee_bot/meshes/1_Link1.STL" scale="0.001 0.001 0.001"/>
      </geometry>
      <material name = "gray A">
		    <color rgba = "0.4660 0.6740 0.1880 1" />
	    </material>
    </visual>

    <collision>
      <origin xyz="0 0 0.0" rpy="0 0 0"/>
      <geometry>
        <mesh filename="package://billee_bot/meshes/1_Link1.STL" scale="0.001 0.001 0.001"/>
      </geometry>
    </collision>

    <inertial>
      <origin xyz="-3.0184870e-04 5.4043684e-04 0.047433" />
      <mass value="0.193211" />
      <inertia ixx="3.4543422e-05" ixy="-1.6031095e-08" ixz="-3.8375155e-07"
               iyy="3.2689329e-05" iyz="2.8511935e-08"
               izz="1.8850320e-05" />
    </inertial>
  </link>

  <!--  Joint 2 -->
  <joint name="joint2" type="revolute">
    <parent link="link1"/>
    <child link="link2"/>
    <origin xyz="0 0 0" rpy="1.57079632679 -1.57079632679 0"/>
    <axis xyz="0 0 1"/>
    <limit velocity="10" effort="1" lower="-1.7907" upper="1.5708" />
  </joint>

  <!--  Link 2 -->
  <link name="link2">
    <visual>
      <origin xyz="0 0 0" rpy="0 0 0"/>
      <geometry>
        <mesh filename="package://billee_bot/meshes/2_Link2.STL" scale="0.001 0.001 0.001"/>
      </geometry>
      <material name = "gray A">
		    <color rgba = "0.4660 0.6740 0.1880 1" />
	    </material>
    </visual>

    <collision>
      <origin xyz="0 0 0" rpy="0 0 0"/>
      <geometry>
        <mesh filename="package://billee_bot/meshes/2_Link2.STL" scale="0.001 0.001 0.001"/>
      </geometry>
    </collision>

    <inertial>
      <origin xyz="1.0308393e-02 3.7743363e-04 1.0170197e-01" />
      <mass value="1.3850917e-01" />
      <inertia ixx="3.3055381e-04" ixy="-9.7940978e-08" ixz="-3.8505711e-05"
               iyy="3.4290447e-04" iyz="-1.5717516e-06"
               izz="6.0346498e-05" />
    </inertial>
  </link>

  <!--  Joint 3 -->
  <joint name="joint3" type="revolute">
    <parent link="link2"/>
    <child link="link3"/>
    <origin xyz="-0.521805 0.0 0.0" rpy="0 0 1.57079632679"/>
    <axis xyz="0 0 1"/>
    <limit velocity="4.8" effort="1" lower="-1.7907" upper="1.7907" />
  </joint>

  <!--  Link 3 -->
  <link name="link3">
    <visual>
      <origin xyz="0 0 0" rpy="0 0 0"/>
      <geometry>
        <mesh filename="package://billee_bot/meshes/3_Link3.STL" scale="0.001 0.001 0.001"/>
      </geometry>
      <material name = "gray A">
		<color rgba = "1 0.6740 0.1880 1" />
	</material>
    </visual>

    <collision>
      <origin xyz="0 0 0" rpy="0 0 0"/>
      <geometry>
        <mesh filename="package://billee_bot/meshes/3_Link3.STL" scale="0.001 0.001 0.001"/>
      </geometry>
    </collision>

    <inertial>
      <origin xyz="9.0909590e-02 3.8929816e-04 2.2413279e-04" />
      <mass value="1.3274562e-01" />
      <inertia ixx="3.0654178e-05" ixy="-1.2764155e-06" ixz="-2.6874417e-07"
               iyy="2.4230292e-04" iyz="1.1559550e-08"
               izz="2.5155057e-04" />
    </inertial>
  </link>

  <!--  Joint 4 -->
  <joint name="joint4" type="revolute">
    <parent link="link3"/>
    <child link="link4"/>
    <origin xyz="-0.159 0 0" rpy="1.57079632679 0 1.57079632679"/>
    <axis xyz="0 0 1"/>
    <limit velocity="4.8" effort="1" lower="-1.7907" upper="2.042" />
  </joint>

  <!--  Link 4 -->
  <link name="link4">
    <visual>
      <origin xyz="0 0 0" rpy="0 0 0"/>
      <geometry>
        <mesh filename="package://billee_bot/meshes/4_Link4.STL" scale="0.001 0.001 0.001"/>
      </geometry>
      <material name = "gray A">
		<color rgba = "0.4660 0.6740 0.1880 1" />
	</material>
    </visual>

    <collision>
      <origin xyz="0 0 0" rpy="0 0 0"/>
      <geometry>
        <mesh filename="package://billee_bot/meshes/4_Link4.STL" scale="0.001 0.001 0.001"/>
      </geometry>
    </collision>

    <inertial>
      <origin xyz="4.4206755e-02 3.6839985e-07 8.9142216e-03" />
      <mass value="1.4327573e-01" />
      <inertia ixx="8.0870749e-05" ixy="0.0" ixz="-1.0157896e-06"
               iyy="7.5980465e-05" iyz="0.0"
               izz="9.3127351e-05" />
    </inertial>
  </link>

  <!--  Joint 5 -->
  <joint name="joint5" type="revolute">
    <parent link="link4"/>
    <child link="link5"/>
    <origin xyz="0 0 -0.526155" rpy="-1.57079632679 1.57079632679 0 "/>
    <axis xyz="0 0 1"/>
    <limit velocity="4.8" effort="1" lower="-1.7907" upper="2.042" />
  </joint>

  <!--  Link 5 -->
  <link name="link5">
    <visual>
      <origin xyz="0 0 0" rpy="0 0 0"/>
      <geometry>
        <mesh filename="package://billee_bot/meshes/5_Link5.STL" scale="0.001 0.001 0.001"/>
      </geometry>
      <material name = "gray A">
		<color rgba = "1 0.6740 0.1880 1" />
	</material>
    </visual>

    <collision>
      <origin xyz="0 0 0" rpy="0 0 0"/>
      <geometry>
        <mesh filename="package://billee_bot/meshes/5_Link5.STL" scale="0.001 0.001 0.001"/>
      </geometry>
    </collision>

    <inertial>
      <origin xyz="4.4206755e-02 3.6839985e-07 8.9142216e-03" />
      <mass value="1.4327573e-01" />
      <inertia ixx="8.0870749e-05" ixy="0.0" ixz="-1.0157896e-06"
               iyy="7.5980465e-05" iyz="0.0"
               izz="9.3127351e-05" />
    </inertial>
  </link>

  <!--  Joint 6 -->
  <joint name="joint6" type="revolute">
    <parent link="link5"/>
    <child link="link6"/>
    <origin xyz="0.030 0 0" rpy="0 1.57079632679 0 "/>
    <axis xyz="0 0 1"/>
    <limit velocity="4.8" effort="1" lower="-1.0" upper="1.0" />
  </joint>

  <!--  Link 6 -->
  <link name="link6">
    <visual>
      <origin xyz="0 0 0" rpy="0 0 0"/>
      <geometry>
        <mesh filename="package://billee_bot/meshes/6_Link6.STL" scale="0.001 0.001 0.001"/>
      </geometry>
      <material name = "gray A">
		<color rgba = "0.4 0.6740 0.1880 1" />
	</material>
    </visual>

    <collision>
      <origin xyz="0 0 0" rpy="0 0 0"/>
      <geometry>
        <mesh filename="package://billee_bot/meshes/6_Link6.STL" scale="0.001 0.001 0.001"/>
      </geometry>
    </collision>

    <inertial>
      <origin xyz="4.4206755e-02 3.6839985e-07 8.9142216e-03" />
      <mass value="1.4327573e-01" />
      <inertia ixx="8.0870749e-05" ixy="0.0" ixz="-1.0157896e-06"
               iyy="7.5980465e-05" iyz="0.0"
               izz="9.3127351e-05" />
    </inertial>
  </link>


  <!-- end effector joint -->
  <joint name="end_effector_joint" type="fixed">
    <origin xyz=" 0.0 0.0 0.071" rpy="1.57079632679 -1.57079632679 0"/>
    <parent link="link6"/>
    <child link="end_effector_link"/>
  </joint>

  <!-- end effector link -->
  <link name="end_effector_link">
    <visual>
      <origin xyz="0 0 0" rpy="0 0 0"/>
      <geometry>
        <box size="0.01 0.01 0.01" />
      </geometry>
      <material name = "gray A">
		<color rgba = "1 0 0 1" />
	</material>
     </visual>

    <inertial>
      <origin xyz="0 0 0" />
      <mass value="1.0e-03" />
      <inertia ixx="1.0e-03" ixy="0.0" ixz="0.0"
               iyy="1.0e-03" iyz="0.0"
               izz="1.0e-03" />
    </inertial>
  </link>

  
</robot>
